Workbook

Sheet DATOS
A1: ESTUDIANTE | B1: PREGRADO | C1: MODALIDAD | D1: POSGRADO | E1: PROFESOR GUIA | F1: PROFESOR COGUIA | G1: TITULO | H1: ANIO PUBLICACION | I1: LICENCIA | J1: AUTORIZACION | K1: ¿EXISTE RESUMEN? | L1: CHECKLIST | M1: RESUMEN | N1: ENLACE | O1: UNIVERSIDAD | P1: DEPARTAMENTO | Q1: AREA_APLICACION | R1: AREA_CONOCIMIENTO | S1: KEYWORDS | T1: AREA_SWEBOK
A2: JUAN PABLO REYES SEPÚLVEDA | B2: INGENIERÍA DE EJECUCIÓN EN COMPUTACIÓN E INFORMÁTICA | C2: VESPERTINA | E2: LUIS RÍOS SEPÚLVEDA | G2: Prototipo de sistema web de apoyo a la gestión de máquinas virtuales en la empresa ADESSA Ltda. | H2: 2015 | I2: Creative Commons AtribuciónNoComercial | J2: AUTORIZADO | K2: SI | L2: =IF(K2 = "SI", EXTRA!$C$3, EXTRA!$C$4) | M2: En este trabajo de título se presenta el desarrollo de un prototipo web de apoyo a la gestión de máquinas virtuales (en adelante, MV) para el área de plataforma de virtualización de la empresa ADESSA Ltda., con el fin de mejorar el actual proceso que involucra la gestión de solicitudes de MV, el cual ha presentado una degradación en el servicio debido al aumento sostenido en la demanda de MV de los clientes de la empresa ADESSA Ltda. Para ello, se diseña e implementa un prototipo que permita obtener indicadores sobre gestión de solicitudes de creación, modificación y eliminación de MV, aportando además a los actores involucrados, información que les permita apoyar la toma decisiones, todo lo anterior en el marco que involucra al área de plataforma de virtualización de ADESSA Ltda. Se hace uso de la metodología OMT++, dado que se trata de un problema mediano en la parte de software y con requerimientos claros desde el principio. El prototipo será puesto a prueba durante el segundo semestre del presente año, donde se espera que al final de dicho período se cuenten con los indicadores que permitan identificar las fortalezas y debilidades del actual proceso de gestión que tiene en la actualidad la plataforma de virtualización. Para poder tomar finalmente como input el prototipo para el desarrollo del sistema final. | N2: https://usach.primo.exlibrisgroup.com/discovery/delivery/56USACH_INST:REPOSITORIO/1226582910006116 | O2: UNIVERSIDAD DE SANTIAGO DE CHILE | P2: DEPARTAMENTO DE INGENIERÍA INFORMÁTICA | Q2: (7) Computer Science | R2: (14) Software Development Fundamentals | S2: gestión, mv, prototipo, adessa, ltda, plataforma, virtualización, actual, desarrollo, empresa | T2: (3) Software Design
A3: ADOLFO ESTEBAN DÍAZ MORALES | B3: INGENIERÍA CIVIL EN INFORMÁTICA | C3: DIURNA | E3: MÓNICA VILLANUEVA ILUFI | G3: Enumeración de conjuntos independientes maximales en grafos tipo Grilla | H3: 2015 | I3: SIN LICENCIA | J3: SIN AUTORIZACIÓN | K3: NO | L3: =IF(K3 = "SI", EXTRA!$C$3, EXTRA!$C$4) | N3: https://usach.primo.exlibrisgroup.com/discovery/delivery/56USACH_INST:REPOSITORIO/1241018680006116 | O3: UNIVERSIDAD DE SANTIAGO DE CHILE | P3: DEPARTAMENTO DE INGENIERÍA INFORMÁTICA | Q3: (28) It does not belong to the computer science field. | R3: (18) It does not belong to the computer science field. | S3: NA | T3: (20) It does not belong to the computer science field.
A4: GABRIEL OSVALDO GÓMEZ ABARCA | B4: INGENIERÍA DE EJECUCIÓN EN COMPUTACIÓN E INFORMÁTICA | C4: VESPERTINA | E4: LUIS RÍOS SEPÚLVEDA | G4: Sistema de monitoreo y alertas para plataformas de servicio en entorno virtual VMWARE | H4: 2015 | I4: Atribución Creative Commons | J4: AUTORIZADO | K4: SI | L4: =IF(K4 = "SI", EXTRA!$C$3, EXTRA!$C$4) | M4: El siguiente trabajo describe el desarrollo de un sistema de apoyo al monitoreo de las plataformas virtuales VMware tanto a nivel de centro de datos como también de computación en la nube, estableciendo para ello su desarrollo sobre plataformas de código abierto y explotado funcionalidades de otras herramientas, como lo es para este caso el motor de Nagios. Durante la evolución del trabajo, las distintas realidades y necesidades de implementación son desarrolladas en base a la metodología de la programación extrema, lo cual permitió a lo largo del proceso de construcción del software, la versatilidad necesaria para construir un sistema funcional, de alto impacto operacional y de nulo coste de implementación, lo que pretende establecer esta herramienta como una alternativa válida para plataformas productivas o de servicios virtualizados sobre VMware. | N4: https://usach.primo.exlibrisgroup.com/discovery/delivery/56USACH_INST:REPOSITORIO/1226596040006116 | O4: UNIVERSIDAD DE SANTIAGO DE CHILE | P4: DEPARTAMENTO DE INGENIERÍA INFORMÁTICA | Q4: (7) Computer Science | R4: (16) Specialized Platform Development | S4: plataformas, desarrollo, implementación, sistema, trabajo, vmware, abierto, alternativa, alto, apoyo | T4: (3) Software Design
A5: GUSTAVO ADOLFO REYES ASPÉ | B5: INGENIERÍA DE EJECUCIÓN EN COMPUTACIÓN E INFORMÁTICA | C5: VESPERTINA | E5: RICARDO CONTRERAS SEPÚLVEDA | G5: Desarrollo de un sistema de información administrativa que apoya la coordinación docente departamental de la Facultad de Ingeniería | H5: 2015 | I5: Creative Commons ReconocimientoNoComercialCompartirIgual | J5: AUTORIZADO | K5: SI | L5: =IF(K5 = "SI", EXTRA!$C$3, EXTRA!$C$4) | M5: El objetivo principal del presente Trabajo de Titulación es el desarrollo de un sistema de información administrativo, que apoye la Coordinación Docente Departamental dentro de la Facultad de Ingeniería de la Universidad de Santiago de Chile. Actualmente, los actores involucrados en la coordinación docente en la Facultad de Ingeniería de la Universidad de Santiago de Chile, utilizan un sistema de información que presenta ciertos inconvenientes en el procesamiento y presentación de la información, dificultando la interacción y operación de los usuarios con el mismo, provocando mermas en la productividad, complejidad innecesaria y retrasos en el proceso global. El sistema desarrollado es una aplicación Web, que a través de una serie de módulos, entrega el apoyo necesario a los actores involucrados en la coordinación, para realizar, por ejemplo, la definición de cursos, asignación de profesores y ayudantes, inscripción de asignaturas por alumno, administración de inscripciones, consulta de información respecto a alumnos, entre otros. Para el desarrollo esta solución, se ha utilizado la metodología orientada a objetos OMT++. A través de la aplicación de la misma, se expone una descripción detallada de los requerimientos, así como de los casos de uso que definen las funcionalidades esenciales del sistema, los cuales son parte fundamental de las entradas para las etapas análisis y diseño de la herramienta. El presente Trabajo de Titulación ha generado una herramienta multiplataforma, que cumple con la totalidad de los requisitos funcionales y no funcionales recolectados, que reduce los tiempos y la complejidad, permitiendo un desenvolvimiento fluido, coherente y eficiente entre sus distintos módulos, convirtiéndose en un mayor apoyo para los involucrados en el proceso de Coordinación Docente. | N5: https://usach.primo.exlibrisgroup.com/discovery/delivery/56USACH_INST:REPOSITORIO/1249698290006116 | O5: UNIVERSIDAD DE SANTIAGO DE CHILE | P5: DEPARTAMENTO DE INGENIERÍA INFORMÁTICA | Q5: (7) Computer Science | R5: (14) Software Development Fundamentals | S5: coordinación, información, sistema, docente, involucrados, actores, aplicación, apoyo, chile, complejidad | T5: (3) Software Design
A6: VICTOR JOSÉ LEBIL LEGUE | B6: INGENIERÍA DE EJECUCIÓN EN COMPUTACIÓN E INFORMÁTICA | C6: VESPERTINA | E6: CAROLINA BONACIC CASTRO | G6: Aplicación de apoyo al proceso de gestión de servicios de taller | H6: 2015 | I6: Creative Commons AtribuciónNoComercial | J6: AUTORIZADO | K6: SI | L6: =IF(K6 = "SI", EXTRA!$C$3, EXTRA!$C$4) | M6: El presente trabajo, se enfoca en la problemática que ocurre en el área de servicios (gestión del taller) de la organización “Autobahn S.A.”. La empresa ha tenido estos inconvenientes desde que se implementó el actual sistema SAP Business One. El principal problema del sistema SAP Business One, es que está orientado a cubrir las principales áreas de una empresa de ventas de productos; finanzas, ventas, compras, inventario, etc., sin abarcar el área de servicio de una empresa. Se aborda dicha problemática, a través del desarrollo de un sistema en ambiente Web, que permita gestionar los servicios de control del taller, mediante la asignación de instaladores a los vehículos detallados en las órdenes de ventas, detalle de estacionamientos, etc. Para el desarrollo de la solución, se utilizan las distintas etapas de la metodología basada en el paradigma de orientación a objetos, OMT++. Finalmente, el sistema permite controlar y realizar seguimiento de todos los vehículos que se encuentran en el taller, mejorando los tiempos de respuesta en cuanto la información requerida, no solo en el área del taller, sino que también en otras áreas de la empresa. | N6: https://usach.primo.exlibrisgroup.com/discovery/delivery/56USACH_INST:REPOSITORIO/1226580850006116 | O6: UNIVERSIDAD DE SANTIAGO DE CHILE | P6: DEPARTAMENTO DE INGENIERÍA INFORMÁTICA | Q6: (7) Computer Science | R6: (14) Software Development Fundamentals | S6: empresa, sistema, taller, ventas, área, business, desarrollo, etc, one, problemática | T6: (3) Software Design
A7: AILEEN LISSETTE ESPARZA VILLAMÁN | B7: INGENIERÍA CIVIL EN INFORMÁTICA | C7: DIURNA | D7: MAGÍSTER EN INGENIERÍA INFORMÁTICA | E7: ROBERTO GONZÁLEZ-IBÁÑEZ | G7: Detección implícita de relevancia percibida de páginas web utilizando registros de actividad del usuario en la búsqueda de información | H7: 2015 | I7: TODOS LOS DERECHOS RESERVADOS | J7: AUTORIZADO | K7: NO | L7: =IF(K7 = "SI", EXTRA!$C$3, EXTRA!$C$4) | N7: https://usach.primo.exlibrisgroup.com/discovery/delivery/56USACH_INST:REPOSITORIO/1226577500006116 | O7: UNIVERSIDAD DE SANTIAGO DE CHILE | P7: DEPARTAMENTO DE INGENIERÍA INFORMÁTICA | Q7: (28) It does not belong to the computer science field. | R7: (18) It does not belong to the computer science field. | S7: NA | T7: (20) It does not belong to the computer science field.
A8: ALEX MAURICIO POBLETE GONZÁLEZ | B8: INGENIERÍA DE EJECUCIÓN EN COMPUTACIÓN E INFORMÁTICA | C8: VESPERTINA | E8: ANDRÉS RICE MORA | G8: Sistema de evaluación interactivo con dispositivos smartphone | H8: 2015 | I8: Creative Commons AtribuciónNoComercial | J8: AUTORIZADO | K8: SI | L8: =IF(K8 = "SI", EXTRA!$C$3, EXTRA!$C$4) | M8: En el presente trabajo de titulación se aborda el problema existente en la Universidad de Santiago de Chile, que se refiere a las tecleras por radio frecuencia, las cuales no están prestando la utilidad prevista, ni están cumpliendo con los objetivos planeados inicialmente para los profesores de la Universidad, los que consistían en hacer un seguimiento del aprendizaje de los alumnos a lo largo del semestre y facilitar la exposición de las materias en clases. Dada la problemática presentada, es que se realiza un análisis y diseño de sistema, que conduce a la construcción de un prototipo que permita a los profesores realizar un correcto seguimiento del avance del proceso de enseñanza-aprendizaje de los estudiantes. La solución planteada es desarrollar una alternativa a las tecleras por radio frecuencia, mediante la utilización de dispositivos móviles (smartphone) y una aplicación de escritorio que permita a los profesores realizar cuestionarios con distintas alternativas y exponerlas en clases para que los estudiantes, puedan realizar la votación a las preguntas expuestas por el profesor. En el presente documento se presenta el proceso de desarrollo del sistema, basándose en un paradigma orientado a objetos y en la utilización de la técnica OMT++, que define la estructura de este documento, especificando para cada una de sus fases los productos generados. Los resultados obtenidos al finalizar el proyecto cumplen con el objetivo general planteado para el proyecto y satisfacen las necesidades especificadas por Unidad de Innovación Educativa (UNIE) de la Universidad de Santiago de Chile. | N8: https://usach.primo.exlibrisgroup.com/discovery/delivery/56USACH_INST:REPOSITORIO/1226483070006116 | O8: UNIVERSIDAD DE SANTIAGO DE CHILE | P8: DEPARTAMENTO DE INGENIERÍA INFORMÁTICA | Q8: (7) Computer Science | R8: (14) Software Development Fundamentals | S8: profesores, realizar, universidad, aprendizaje, chile, clases, documento, estudiantes, frecuencia, permita | T8: (3) Software Design
A9: BASTIÁN FELIPE GANGA PEÑA | B9: INGENIERÍA DE EJECUCIÓN EN COMPUTACIÓN E INFORMÁTICA | C9: VESPERTINA | E9: ROSA MUÑOZ CALANCHIE | G9: Aplicación interactiva sobre dispositivo Touch-Screen, con el objetivo de mejorar la atención de clientes en Delightchile | H9: 2015 | I9: Atribución Creative Commons | J9: AUTORIZADO | K9: SI | L9: =IF(K9 = "SI", EXTRA!$C$3, EXTRA!$C$4) | M9: La medición de la calidad de atención al cliente se ha convertido en una herramienta importante para evaluar los protocolos de atención de las empresas, detectando fortalezas y debilidades, cuyos resultados son de gran utilidad para tomar medidas de mitigación con el objetivo de marcar la diferencia con otras marcas de la competencia, logrando fidelizar a sus clientes y captar nuevos. Para las empresas, es importante contar con esta información lo más pronto posible, lo que se complica cuando no existe ningún sistema que pueda entregar esta información. Para ello es que el objetivo de este trabajo de titulación, desarrollar un sistema informático interactivo y que cuenta con un sistema de evaluación de atención hacia los clientes. Para realizar este proyecto se utilizó una metodología basada en un modelo de desarrollo de Prototipos de software, modelo adecuado cuando el cliente tiene claro los objetivos generales del sistema, pero éste no identifica los requisitos detallados de entrada, procedimiento o salida. Es un modelo de desarrollo evolutivo, en el que el prototipo debe ser construido en poco tiempo, realizando entregas periódicas para su revisión y posteriores mejoras, hasta llegar al prototipo final utilizando pocos recursos. Como resultado del desarrollo, se obtiene un software que cumple con las características de un sistema embebido diseñado para cubrir las necesidades específicas de la empresa, además de ser portable y accesible con o sin Internet dentro de un sistema touch screen. Finalmente, uno de los aspectos que se destacan en la implementación del sistema, es el módulo de catálogo de productos que ofrece una auto atención para los clientes que visitan las distintas sucursales de DelightChile, apoyando así el proceso de atención de estos, se reducen los tiempos de espera y se evitan las filas de atención para los clientes. También con el nuevo software se comienza a conocer como son atendidos los clientes, ya que estos deben evaluar el desempeño de los vendedores en las sucursales, llenando los formularios y calificandolos con una nota de 1 a 5. | N9: https://usach.primo.exlibrisgroup.com/discovery/delivery/56USACH_INST:REPOSITORIO/1226636460006116 | O9: UNIVERSIDAD DE SANTIAGO DE CHILE | P9: DEPARTAMENTO DE INGENIERÍA INFORMÁTICA | Q9: (7) Computer Science | R9: (15) Software Engineering | S9: sistema, atención, clientes, desarrollo, modelo, software, cliente, empresas, evaluar, importante | T9: (3) Software Design
A10: FELIPE ALEJANDRO LAGOS BECERRA | B10: INGENIERÍA DE EJECUCIÓN EN COMPUTACIÓN E INFORMÁTICA | C10: VESPERTINA | E10: LUIS RÍOS SEPÚLVEDA | G10: Sistema web de apoyo a la gestión de franquicias médicas-dentales para alumnos de la Universidad de Chile | H10: 2015 | I10: Creative Commons AtribuciónNoComercial | J10: AUTORIZADO | K10: SI | L10: =IF(K10 = "SI", EXTRA!$C$3, EXTRA!$C$4) | M10: En este trabajo de titulación se presenta el diseño e implementación de un sistema, para dar solución al problema en la asignación de franquicias médicas y dentales que son beneficios otorgados a alumnos de la Universidad de Chile. Dicho problema se genera debido a ubicación geográfica de los centros de atención, ya que los diversos actores no visualizan el estado de la solicitud del beneficio, implicando dificultades comunicacionales. El sistema que se diseña e implementa como solución de apoyo a la gestión de franquicias médicas – dentales, y agiliza el flujo para una mejor entrega del beneficios. Para desarrollar este sistema, se utiliza el paradigma orientado a objetos y basado en la metodología OMT++, la cual, comienza con la toma de requerimientos, finalizando con las pruebas al sistema, con lo que se obtiene el producto requerido. | N10: https://usach.primo.exlibrisgroup.com/discovery/delivery/56USACH_INST:REPOSITORIO/1226601990006116 | O10: UNIVERSIDAD DE SANTIAGO DE CHILE | P10: DEPARTAMENTO DE INGENIERÍA INFORMÁTICA | Q10: (7) Computer Science | R10: (15) Software Engineering | S10: sistema, beneficios, dentales, franquicias, médicas, problema, solución, actores, agiliza, alumnos | T10: (3) Software Design
A11: JUAN PABLO VERDEJO JORQUERA | B11: INGENIERÍA DE EJECUCIÓN EN COMPUTACIÓN E INFORMÁTICA | C11: VESPERTINA | E11: FERNANDO RANNOU FUENTES | G11: Herramienta de diseño de configuraciones atómicas y visualización de resultados para simulación de campo magnético | H11: 2015 | I11: Creative Commons AtribuciónNoComercialCompartirIgual | J11: AUTORIZADO | K11: SI | L11: =IF(K11 = "SI", EXTRA!$C$3, EXTRA!$C$4) | M11: Investigadores del Departamento de Física de la Universidad de Santiago de Chile simulan los efectos del campo magnético en los átomos de distintos objetos. El proceso de diseño de configuraciones atómicas y de visualización de resultados de aquellas simulaciones es manual, lo que hace que el tiempo necesario para ejecutar dichas tareas sea alto. Es necesario desarrollar una aplicación que permita mejorar los procesos actuales, tanto de diseño de configuraciones atómicas como de visualización de los resultados. Para solucionar este problema, se diseña y crea una aplicación en Python que permite diseñar rápidamente las configuraciones atómicas con todas sus características físicas. Estas configuraciones atómicas pueden ser validadas inmediatamente mediante una visualización 3D generada con OpenGL y descargadas como imagen para publicaciones. La herramienta permite, además, visualizar los resultados de la simulación en 3D analizando los vectores de magnetización para cada átomo en cada uno de los pasos Monte Carlo ejecutados en la simulación. Estos resultados pueden ser exportados para publicaciones o conferencias como imágenes o videos. El desarrollo se basa en una modificación a la metodología Scrum. Estas son necesarias, ya que la metodología está pensada para equipos de desarrollo compuestos por ma ́s de una persona. Dichas modificaciones se refieren, principalmente, a las distintas reuniones del equipo de desarrollo que la metodología define, también conocidas como ceremonias en la terminología Scrum, y que fueron adaptadas para este caso particular. La aplicación desarrollada está siendo usada actualmente por dos alumnos de doctorado en sus tesis. Esto ha permitido que tareas que anteriormente tomaban horas, incluso días, puedan ser ejecutadas en solo minutos. Gracias a esto, los investigadores disponen de más tiempo para analizar los resultados, que pueden ser utilizados en nuevas aplicaciones que nos permitan avanzar como sociedad. | N11: https://usach.primo.exlibrisgroup.com/discovery/delivery/56USACH_INST:REPOSITORIO/1226531300006116 | O11: UNIVERSIDAD DE SANTIAGO DE CHILE | P11: DEPARTAMENTO DE INGENIERÍA INFORMÁTICA | Q11: (24) Physics and Astronomy | R11: (16) Specialized Platform Development | S11: resultados, atómicas, configuraciones, ser, aplicación, desarrollo, metodología, pueden, visualización, cada | T11: (3) Software Design
A12: CRISTOPHER ERNESTO MUÑOZ SANDOVAL | B12: INGENIERÍA DE EJECUCIÓN EN COMPUTACIÓN E INFORMÁTICA | C12: VESPERTINA | E12: MÓNICA VILLANUEVA ILUFI | G12: Enumeración de conjuntos independientes maximales en gráficos K-Tree | H12: 2015 | I12: Creative Commons AtribuciónNoComercialCompartirIgual | J12: AUTORIZADO | K12: SI | L12: =IF(K12 = "SI", EXTRA!$C$3, EXTRA!$C$4) | M12: En 1984 Leung resuelve el problema de enumeración de conjuntos independientes maximales (cim) en grafos cordales (también llamados triangulados), creando un algoritmo con complejidad temporal de orden O((n + e) * m) , siendo n el número de nodos, e el número de aristas y m el número de conjuntos independientes maximales. Un grafo completo con k nodos es un grafo perteneciente a la clase k-tree, dado un k fijo. Si G es un k-tree y C es un k-clique de G, entonces el grafo formado al añadir un nuevo vértice a G, y haciéndolo adyacente a todos los nodos de C, es un k-tree. El presente trabajo aborda el problema de la enumeración de conjuntos independientes maximales en grafos k-tree, una subclase de los grafos cordales. Si bien el algoritmo de Leung es efectivo para los grafos k-tree, estos últimos poseen la “propiedad constructiva” que en palabras simples dice que un grafo k-tree puede ser formado añadiendo nodos a otro grafo k- tree inicial. En base a esto el presente trabajo toma el siguiente enfoque: Sea G un grafo perteneciente a la clase k-tree, y sea CIM(G) su familia de conjuntos independientes maximales. Si se añade un nuevo nodo v a G, haciéndolo adyacente al algún k-clique de G, obteniendo el grafo G+v, ¿es posible obtener los conjuntos independientes maximales de G+v a partir de CIM(G)? Como resultado de este trabajo se presenta un algoritmo que, en base a los conjuntos independientes maximales de un grafo k-tree, enumera la familia de conjuntos independientes maximales al agregar un nuevo nodo al grafo. El algoritmo desarrollado tiene una complejidad temporal de orden O(m2 * n). | N12: https://usach.primo.exlibrisgroup.com/discovery/delivery/56USACH_INST:REPOSITORIO/1226544890006116 | O12: UNIVERSIDAD DE SANTIAGO DE CHILE | P12: DEPARTAMENTO DE INGENIERÍA INFORMÁTICA | Q12: (7) Computer Science | R12: (1) Algorithms and Complexity | S12: k, g, grafo, tree, conjuntos, independientes, maximales, algoritmo, grafos, nodos | T12: (19) Research/Investigation
A13: ARTURO MENDOZA URTEAGA | B13: INGENIERÍA CIVIL EN INFORMÁTICA | C13: VESPERTINA | E13: EDMUNDO LEIVA LOBOS | G13: Sistema de captura sincronizada de registros multimodales de la interacción humana computador para posteriormente reconocer episodios de sonrisa | H13: 2015 | I13: Creative Commons AtribuciónNoComercialCompartirIgual | J13: AUTORIZADO | K13: SI | L13: =IF(K13 = "SI", EXTRA!$C$3, EXTRA!$C$4) | M13: El presente trabajo de titulación tiene por objetivo desarrollar la primera versión de un ambiente de experimentación basado en un mecanismo de sincronización y visualización de videos para el reconocimiento de patrones que aparecen en las sonrisas. Esta solución se ha desarrollado como respuesta a los procesos que un experto de la computación afectiva realiza en el contexto de la detección del engaño cuando la gente sonríe. Dicho esto, el problema de sincronizar videos para los distintos canales resulta ineficiente si son efectuados a través de procesos manuales. En el mundo real, los protocolos de pregunta/respuesta establecidos por policías, seleccionadores de recursos humanos, investigadores y terapeutas para llevar a los sujetos a tener contradicciones son comúnmente acompañados de sonrisas que a su vez dan indicios de engaño, pero es preciso analizarlas en detalle. El prototipo asociado a esta memoria fue construido con la metodología RAD y utiliza patrón de diseño MVC garantizando que el ambiente sea escalable en el tiempo. La solución consistió en inicializar u organizar los aspectos temporales de la información transportada en un sistema de múltiples canales pero solamente cuando los canales puedan ser llevados a videos. En su uso real, la aplicación espera que el sujeto sonría después de una pregunta de un caza mentiras (que está conectado por video conferencia). En uso de investigación, el proceso genera archivos físicos “logs” que pueden ser utilizados por el investigador en computación afectiva para el análisis a posteriori de datos capturados. Por otro lado, la visualización de videos consistió en un reproductor web que permite cargar videos y reproducirlos de forma simultánea. En resumen, el software construido permite la captura del rostro de la persona frente al monitor (FaceRecorder), lo que él o ella enfoca su atención sobre la pantalla (EyeTribe) y lo que muestra la interfaz (ActivityRender). | N13: https://usach.primo.exlibrisgroup.com/discovery/delivery/56USACH_INST:REPOSITORIO/1226518900006116 | O13: UNIVERSIDAD DE SANTIAGO DE CHILE | P13: DEPARTAMENTO DE INGENIERÍA INFORMÁTICA | Q13: (7) Computer Science | R13: (15) Software Engineering | S13: videos, canales, afectiva, ambiente, computación, consistió, construido, engaño, permite, pregunta | T13: (3) Software Design
A14: ALONSO LEONIDAS INOSTROSA PSIJAS | B14: - | D14: DOCTORADO EN CIENCIAS DE LA INGENIERÍA, MENCIÓN INGENIERÍA INFORMÁTICA | E14: JUAN MAURICIO MARÍN CAIHUAN | F14: GRACIELA VERÓNICA GIL COSTA | G14: Simulaciones aproximadas semi-asíncronas en Devs con aplicación en motores de búsqueda web | H14: 2015 | I14: SIN LICENCIA | J14: SIN AUTORIZACIÓN | K14: NO | L14: =IF(K14 = "SI", EXTRA!$C$3, EXTRA!$C$4) | N14: https://usach.primo.exlibrisgroup.com/discovery/delivery/56USACH_INST:REPOSITORIO/1249699810006116 | O14: UNIVERSIDAD DE SANTIAGO DE CHILE | P14: DEPARTAMENTO DE INGENIERÍA INFORMÁTICA | Q14: (28) It does not belong to the computer science field. | R14: (18) It does not belong to the computer science field. | S14: NA | T14: (20) It does not belong to the computer science field.
A15: FERNANDO ANTONIO RODRÍGUEZ HERRERA | B15: INGENIERÍA CIVIL EN INFORMÁTICA | C15: VESPERTINA | E15: ALCIDES QUISPE SANCA | G15: Rediseño y propuesta de software para la gestión del proceso realizado en el cobro de facturas de servicios de proveedores en una inmobiliaria | H15: 2015 | I15: Atribución Creative Commons | J15: AUTORIZADO | K15: SI | L15: =IF(K15 = "SI", EXTRA!$C$3, EXTRA!$C$4) | M15: Este trabajo de titulación coloca a disposición de la comunidad, el cómo se rediseñó el proceso que realizaba el Departamento de Contabilidad de una inmobiliaria, para hacer efectivo el cobro por servicios prestados por proveedores de las obras que tiene en funcionamiento y el desarrollo de un sistema de software, el cual permite gestionar el proceso completo. Se inició el rediseño del proceso, realizando un análisis y modelamiento de éste en BPMN (Modelo y Notación de Procesos de Negocio), lo cual permitió identificar todas las tareas y roles. Posteriormente ya teniendo el modelo del proceso, se identificaron las problemáticas que afectan a éste, de manera de atacar estos problemas desde su raíz, lo cual se logró reorganizando tareas y roles, agregando y eliminando tareas del proceso. Una vez obtenido el nuevo proceso, este fue utilizado como columna vertebral en el desarrollo del sistema de software, el cual se encuentra dividido en una interfaz de escritorio y una Web. De estas dos interfaces se desarrollada únicamente la primera de éstas, utilizando para esto la metodología ágil scrum. La aplicación desarrollada es utilizada dentro de las dependencias de la empresa por la recepcionista y las administrativas de proveedores, para gestionar las facturas, notas de crédito y cartas de factoraje recibidas y generar los envíos a aprobación de las facturas, de manera que la obra indique si el cobro corresponde y hacerlo efectivo. Finalmente, el trabajo concluye con la medición del grado de satisfacción que tienen los usuarios con el nuevo proceso de cobro y el sistema de software que lo gestiona. | N15: https://usach.primo.exlibrisgroup.com/discovery/delivery/56USACH_INST:REPOSITORIO/1226569580006116 | O15: UNIVERSIDAD DE SANTIAGO DE CHILE | P15: DEPARTAMENTO DE INGENIERÍA INFORMÁTICA | Q15: (4) Business, Management and Accounting | R15: (15) Software Engineering | S15: proceso, cobro, sistema, software, tareas, desarrollada, desarrollo, efectivo, facturas, gestionar | T15: (3) Software Design
A16: JAVIER ANDRÉS HENRÍQUEZ ACEVEDO | B16: INGENIERÍA CIVIL EN INFORMÁTICA | C16: VESPERTINA | E16: MÓNICA VILLANUEVA ILUFI | G16: Sistema de gestión de postulantes de la Universidad Diego Portales a becas del Ministerio de Educación | H16: 2015 | I16: Creative Commons AtribuciónNoComercial | J16: AUTORIZADO | K16: SI | L16: =IF(K16 = "SI", EXTRA!$C$3, EXTRA!$C$4) | M16: En la Universidad Diego Portales no se informan correctamente los antecedentes académicos de aquellos alumnos que postulan a becas del Ministerio de Educación, provocando con ello, la pérdida del respaldo económico, que debe asumir la Universidad. La solución comprende el modelamiento del proceso de respaldo de postulantes UDP, para posteriormente diseñar y desarrollar una plataforma Web que apoye estos procesos, lo que permite informar oportuna y correctamente los postulantes en la plataforma Web que dispone el MINEDUC. La solución se divide en módulos que apoyan los procesos de alumnos nuevos que ingresan por primera vez a un programa de estudios dentro de la Universidad, alumnos antiguos en la UDP que nunca han postulado a una beca ministerial además de aquellos alumnos que renuevan su beneficio anualmente, finalmente postulantes que son beneficiados con la beca de reparación Valech, ya sean, titulares, hijos o nietos. En la etapa de diseño, a través de reuniones con el usuario final, se formalizaron los requerimientos funcionales; a partir de éstos, se construyeron casos de uso y el modelo de interfaz de usuario, lo anterior es fundamental para determinar como el usuario final interactúa con la plataforma Web, además es la hoja de ruta para el desarrollo. Para comprobar la correlación entre estos elementos se elaboraron matrices de trazabilidad. Para asegurar persistencia y consistencia de los datos se construyó una base de datos que permite almacenar y acceder a éstos de forma rápida y estructurada. Para el desarrollo del sistema se utiliza el patrón de diseño modelo vista controlador (MVC), este patrón permite separar la interfaz de usuario (vista), de la lógica de negocios (controlador) y la base de datos (modelo) De acuerdo a las pruebas realizadas se pudo determinar que la aplicación funciona para la totalidad de los casos de prueba ejecutados. | N16: https://usach.primo.exlibrisgroup.com/discovery/delivery/56USACH_INST:REPOSITORIO/1226610300006116 | O16: UNIVERSIDAD DE SANTIAGO DE CHILE | P16: DEPARTAMENTO DE INGENIERÍA INFORMÁTICA | Q16: (7) Computer Science | R16: (15) Software Engineering | S16: alumnos, usuario, datos, modelo, permite, plataforma, postulantes, universidad, web, además | T16: (3) Software Design
A17: LEONARDO ALEXIS CABRERA LOBOS | B17: INGENIERÍA CIVIL EN INFORMÁTICA | C17: DIURNA | E17: ROSA MUÑOZ CALANCHIE | G17: Desarrollo de un Framework para la construcción de objetos de aprendizaje | H17: 2015 | I17: Creative Commons AtribuciónNoComercial | J17: AUTORIZADO | K17: SI | L17: =IF(K17 = "SI", EXTRA!$C$3, EXTRA!$C$4) | M17: El presente trabajo documenta el proceso de desarrollo de un framework para apoyar la construcción de objetos de aprendizaje. Dicho framework se implementó basándose en la metodología CPIS para la construcción de los mismos. La motivación de este trabajo surge a partir de la detección de la necesidad de normalizar los procesos de software asociados a la construcción de objetos de aprendizaje y, al mismo tiempo, las bases de código que los constituyen. Para su generación, se hizo una revisión de los conceptos que caracterizan los objetos de aprendizaje y se estudió en profundidad la metodología antes mencionada. Luego, se aplicaron métodos de ingeniería de software para determinar los requerimientos de usuario y software. Posteriormente se realizó una caracterización técnica del framework en cada aspecto del mismo. Finalmente, se implementó el software de acuerdo a las especificaciones documentadas y las tecnologías escogidas. Para su validación, se construyó un objeto de aprendizaje utilizando tanto la metodología CPIS como el framework. Al mismo tiempo, se aprovecharon las cualidades que el framework provee para optimizar procesos dentro de dicha metodología. El producto resultante es un software que puede ser utilizado y reutilizado en la construcción de objetos de aprendizaje futuros. | N17: https://usach.primo.exlibrisgroup.com/discovery/delivery/56USACH_INST:REPOSITORIO/1226636390006116 | O17: UNIVERSIDAD DE SANTIAGO DE CHILE | P17: DEPARTAMENTO DE INGENIERÍA INFORMÁTICA | Q17: (7) Computer Science | R17: (15) Software Engineering | S17: aprendizaje, framework, software, construcción, metodología, objetos, mismo, cpis, implementó, procesos | T17: (3) Software Design
A18: GABRIEL ANTONIO SALAZAR MORENO | B18: INGENIERÍA CIVIL EN INFORMÁTICA | C18: DIURNA | E18: ROSA MUÑOZ CALANCHIE | G18: Reingeniería de objetos de aprendizaje para ser usados ​​en múltiples dispositivos | H18: 2015 | I18: Creative Commons AtribuciónNoComercialCompartirIgual | J18: AUTORIZADO | K18: SI | L18: =IF(K18 = "SI", EXTRA!$C$3, EXTRA!$C$4) | M18: El presente trabajo de titulación muestra el proceso del cambio de diseño de material pedagógico de apoyo en formato de Objetos de Aprendizaje (OAs), para que éstos puedan ser usados en múltiples dispositivos como computadores de escritorio y dispositivos móviles como tablets y smartphones, independientemente del hardware y del software con el cual funcionen estos dispositivos. Debido a que los Objetos de Aprendizaje usados en los cursos de “Redes de Comunicación” y “Criptografía y Protocolos de Seguridad” del Departamento de Ingeniería Informática de la Universidad de Santiago están disponibles en formato Flash, y sumado a que este formato ha quedado obsoleto y las actuales plataformas están migrando hacia nuevos estándares de contenido Web, se hace necesario transformar estos OAs para que los alumnos de estos cursos u otros similares puedan hacer uso de ellos en los dispositivos que usan con frecuencia, y de esta forma recuperar los OAs para apoyar el proceso de enseñanza en estas asignaturas. Para el rediseño de estos OAs se realizó un breve análisis a distintos trabajos de titulación en que se desarrollaron los mismos y luego se utilizó una metodología que consta de cuatro etapas: análisis, diseño, construcción y pruebas. El resultado de estas fases son nuevos OAs que pueden ser usados independientemente de la plataforma que el alumno decida usar, usando estándares actuales como HTML5. El desarrollo de los nuevos OAs incorpora las recomendaciones sobre usabilidad y funcionalidades que los expertos en estos temas recomendaron a los autores de los Objetos de Aprendizaje originales, particularmente en las actividades y evaluaciones que los nuevos Objetos de Aprendizaje ofrecen a los alumnos. | N18: https://usach.primo.exlibrisgroup.com/discovery/delivery/56USACH_INST:REPOSITORIO/1226546170006116 | O18: UNIVERSIDAD DE SANTIAGO DE CHILE | P18: DEPARTAMENTO DE INGENIERÍA INFORMÁTICA | Q18: (7) Computer Science | R18: (14) Software Development Fundamentals | S18: oas, aprendizaje, dispositivos, nuevos, objetos, formato, usados, actuales, alumnos, análisis | T18: (3) Software Design
A19: FELIPE ANTONIO IRIBARREN VIERTEL | B19: INGENIERÍA CIVIL EN INFORMÁTICA | C19: DIURNA | E19: ROSA MUÑOZ CALANCHIE | G19: Desarrollo de un objetivo de aprendizaje para apoyar el estudio de Android | H19: 2015 | I19: Creative Commons AtribuciónNoComercial | J19: AUTORIZADO | K19: SI | L19: =IF(K19 = "SI", EXTRA!$C$3, EXTRA!$C$4) | M19: Con el constante avance de las tecnologías y la cada vez más integración de ésta en la vida cotidiana de las personas, los Objetos de Aprendizaje cada día toman mayor relevancia, puesto que ellos presentan los contenidos de manera didáctica e interactiva que resulta más interesante para las personas. Sin ir más lejos, los mismos estudiantes universitarios actualmente están altamente familiarizados con las tecnologías, lo cual permite a través de imágenes y animaciones entregar los conceptos básicos de la programación en Android, que en la actualidad, es uno de los principales sistemas operativos para dispositivos móviles. Para lograrlo, se desarrolla un Objeto de Aprendizaje orientado a los estilos de aprendizaje predominantes en el grupo de usuarios del mismo y utilizando la metodología CPIS y la herramienta Adobe Edge Animate CC 2014. Finalmente, el Objeto de Aprendizaje desarrollado fue validado en tres aspectos: evaluación del experto, cumplimiento de los requerimientos y evaluación de los usuarios objetivo. El resultado principal de este trabajo es un Objeto de Aprendizaje en HTML5 que aborda los conceptos básicos de la programación en Android junto con un documento que presenta el marco teórico referente al tema y las consideraciones tomadas para su desarrollo. Con esto, se permite que cualquier interesado en el tema pueda estudiar los conceptos básicos que le permitan sentar cimientos conceptuales sólidos para afrontar la codificación misma de una aplicación Android. | N19: https://usach.primo.exlibrisgroup.com/discovery/delivery/56USACH_INST:REPOSITORIO/1226596570006116 | O19: UNIVERSIDAD DE SANTIAGO DE CHILE | P19: DEPARTAMENTO DE INGENIERÍA INFORMÁTICA | Q19: (7) Computer Science | R19: (14) Software Development Fundamentals | S19: aprendizaje, android, básicos, conceptos, objeto, cada, evaluación, permite, personas, programación | T19: (3) Software Design
A20: MAURICIO LEONEL CARÚS FLORES | B20: INGENIERÍA CIVIL EN INFORMÁTICA | C20: DIURNA | E20: ROSA MUÑOZ CALANCHIE | G20: Generador de objetos de aprendizaje basados en metodología CPIS | H20: 2015 | I20: Creative Commons AtribuciónNoComercial | J20: AUTORIZADO | K20: SI | L20: =IF(K20 = "SI", EXTRA!$C$3, EXTRA!$C$4) | M20: Con el objeto de apoyar a los académicos de la Universidad Academia de Humanismo Cristiano (UAHC) en la entrega de material de apoyo para las diferentes materias que enseñan en las carreras que imparte la Universidad, es que se considera la aplicación de objetos de aprendizaje. No obstante, el desconocimiento de los académicos de estas herramientas, sus características, requerimientos y actualización en el tiempo son factores que ven como trabas a la hora de aplicar este tipo de herramientas en su uso cotidiano como apoyo a la enseñanza. Para solucionar esta problemática es que se propone la creación de una aplicación que apoye a los docentes en el proceso de creación, evaluación y mantención de objetos de aprendizaje, basada en una metodología de creación de OA originada en las dependencias de la Universidad de Santiago de Chile, denominada metodología CPIS. Por otro lado, para llevar a cabo la realización del sistema propuesto, se utiliza una metodología de desarrollo de aplicaciones (OMT++ Simplificado), que permite un proceso estructurado e iterativo de desarrollo de sistemas computacionales, la cual detalla cada una de sus etapas con artefactos que apoyan la toma de requerimientos, el análisis, el diseño y la programación del futuro sistema. El resultado principal de este trabajo es la aplicación “CPIS Manager”, que es un sistema computacional que permite guiar al usuario en la creación de objetos de aprendizaje utilizando la metodología CPIS, de modo que los académicos de la UAHC puedan ser capaces de crear sus propios OA, evaluarlos y modificarlos en el tiempo. | N20: https://usach.primo.exlibrisgroup.com/discovery/delivery/56USACH_INST:REPOSITORIO/1226565710006116 | O20: UNIVERSIDAD DE SANTIAGO DE CHILE | P20: DEPARTAMENTO DE INGENIERÍA INFORMÁTICA | Q20: (7) Computer Science | R20: (14) Software Development Fundamentals | S20: creación, metodología, académicos, aplicación, aprendizaje, cpis, objetos, sistema, universidad, apoyo | T20: (3) Software Design
A21: JUAN PABLO LEÓN ARCE | B21: INGENIERÍA CIVIL EN INFORMÁTICA | C21: DIURNA | E21: ROSA MUÑOZ CALANCHIE | G21: Objeto de aprendizaje para apoyar el aprendizaje de la herramienta OMNET++ | H21: 2015 | I21: Creative Commons AtribuciónNoComercialCompartirIgual | J21: AUTORIZADO | K21: SI | L21: =IF(K21 = "SI", EXTRA!$C$3, EXTRA!$C$4) | M21: En el presente trabajo de titulación se desarrolla un Objeto de aprendizaje (OA) cuyo propósito es aportar en la disminución de los tiempos de aprendizaje de la herramienta de simulación Omnet ++ utilizada por los estudiantes del curso de Redes de Comunicación de la Universidad de Santiago de Chile. El desarrollo del trabajo se realizó bajo la método ágil CPIS la cual está enfocada en la creación de OAs mediante la aplicación de las fases de definición, selección de material, diseño, construcción y evaluación de calidad, donde la última etapa fue realizada utilizando el método propuesto por Álvaro Salas el cual consiste en que tres expertos realicen la evaluación de calidad del objeto revisando aspectos pedagógicos, técnicos y de usabilidad. Se logró la creación de 3 OAs. El primero de ellos es del tipo conceptual cuyo contenido se enfoca en describir el uso de la herramienta Omnet y de los lenguajes de programación NED y C++ asociados a éste. El segundo es del tipo procedimental donde se insta a los alumnos a realizar su primera simulación en Omnet++. El último de ellos es del tipo procedimental donde se explica cómo instalar y configurar la herramienta Omnet++. La prueba de uso de los objetos fue realizada por dos grupos de usuarios los cuales utilizaron y realizaron las actividades propuestas en éstos. El primer grupo se compuso por alumnos del curso de Redes de Comunicación en una de las Salas del Departamento de Informática de la Universidad de Santiago de Chile, mientras que el segundo grupo fue conformado por voluntarios desde sus propios hogares. Los datos de la prueba de uso de los objetos y de calidad permiten concluir que estos OAs cumplen su función de enseñar los conceptos básicos de un modelo Omnet++ y de guiar al usuario a realizar su primera simulación en Omnet. | N21: https://usach.primo.exlibrisgroup.com/discovery/delivery/56USACH_INST:REPOSITORIO/1226493000006116 | O21: UNIVERSIDAD DE SANTIAGO DE CHILE | P21: DEPARTAMENTO DE INGENIERÍA INFORMÁTICA | Q21: (7) Computer Science | R21: (14) Software Development Fundamentals | S21: omnet, calidad, herramienta, oas, simulación, tipo, uso, alumnos, aprendizaje, chile | T21: (1) Software Requirements
A22: MARCELO ANTONIO MADARIAGA MORENO | B22: INGENIERÍA CIVIL EN INFORMÁTICA | C22: DIURNA | E22: SERGIO VELASTÍN CARROZA | G22: Comparación de aplicaciones para la detección de vehículos detenidos en sectores prohibidos del tráfico urbano | H22: 2015 | I22: Creative Commons AtribuciónNoComercial | J22: AUTORIZADO | K22: SI | L22: =IF(K22 = "SI", EXTRA!$C$3, EXTRA!$C$4) | M22: En el presente trabajo de titulación se pretende solucionar la detección de vehículos detenidos en sectores prohibidos del tráfico urbano, teniendo como iniciativa, el proyecto del Ministerio de Transporte que hace referencia a la detección de vehículos que se detengan en las intersecciones de avenidas, donde existe la ley del tránsito “no bloquear el cruce”. La solución propuesta para esta problemática es evaluar sistemas comerciales que resuelvan esta problemática mediante visión por computador, determinando qué sistema tiene mayor desempeño en la detección de vehículos en tiempo real. Los sistemas comerciales participantes en este trabajo son Ipsotek y Acic, líderes mundiales en soluciones de esta índole. Para poder determinar qué sistema comercial obtiene un mayor desempeño en la video analítica, es construida una base de datos de video en conjunto con Centro Estratégico de Fiscalización, CEF, con el fin de realizar una evaluación de desempeño a los sistemas comerciales antes mencionados. La evaluación de desempeño de los sistemas comerciales se llevó a cabo en base a las siguientes métricas: tales como precision, recall y F1-Measure. Un sistema comercial debe cumplir criterios de aceptación, los cuales fueron definidos en base a la documentación de i-Lids Dataset (CAST and CPNI, 2011) y el Centro Estratégico de Fiscalización. Se establece que los sistemas comerciales deben tener un score de 0.7 en la métrica de evaluación F1-Measure. Los resultados obtenidos en base a la configuración y evaluación de desempeño de los sistemas comerciales, fueron favorables para el sistema comercial Acic Video Analitycs, con un score en la métrica F1-Measure de 0.4. | N22: https://usach.primo.exlibrisgroup.com/discovery/delivery/56USACH_INST:REPOSITORIO/1226610110006116 | O22: UNIVERSIDAD DE SANTIAGO DE CHILE | P22: DEPARTAMENTO DE INGENIERÍA INFORMÁTICA | Q22: (7) Computer Science | R22: (3) Artificial Intelligence | S22: comerciales, sistemas, desempeño, base, evaluación, sistema, comercial, detección, f, measure | T22: (5) Software Testing
A23: MIGUEL ANGEL MALDONADO ALGÜERNA | B23: INGENIERÍA CIVIL EN INFORMÁTICA | C23: DIURNA | E23: ROSA MUÑOZ CALANCHIE | G23: Sistema de cálculo de reservas : técnicas para seguros generales | H23: 2015 | I23: SIN LICENCIA | J23: SIN AUTORIZACIÓN | K23: SI | L23: =IF(K23 = "SI", EXTRA!$C$3, EXTRA!$C$4) | M23: Los constantes cambios tecnológicos y normativos a los que están expuestas las grandes empresas, llevan a que estás inviertan grandes cantidades de dinero en procesos de desarrollo y mantención de sus sistemas Es así como en el presente trabajo se muestra una necesidad en la Compañía de Seguros Consorcio, necesidad que nace desde la obsolescencia de los procesos y tecnologías. Siendo apalancada por la gran cantidad de problemas y elementos de riesgo que conlleva el mantenerla sin cambios. El problema que se presenta, consiste en la definición e implementación (interna y externa) de un nuevo sistema para el Cálculo de las Reservas Técnicas para Seguros Generales. Proceso que se llevó por cerca de dos años de forma poco eficiente y riesgosa. La solución, considera tanto los aspectos funcionales como no funcionales requeridos en Consorcio. Es por ello que se buscaron las siguientes características a la hora de la implementación: proceso eficiente, que controle errores, que sea auditable y que sea centralizado. El desarrollo se separa en dos vías, una ejecutada por un proveedor externo a Consorcio y otra por el área tecnológica de la compañía. Es por lo anterior, que en el documento se hace énfasis al desarrollo del proceso de carga de datos de entrada, que es la parte desarrollada por Consorcio. Una vez construido el sistema, se obtuvieron y compararon los resultados con el proceso anterior, llegando a ver una notable mejora en los tiempos de procesamiento de los cálculos. Además de, una notable mejora en la experiencia de usuario. Llegando a un sistema que cumple con la normativa interna y externa, que realiza sus procesos de forma rápida y confiable, y que permite una mayor independencia de los usuarios finales. | N23: https://usach.primo.exlibrisgroup.com/discovery/delivery/56USACH_INST:REPOSITORIO/1241018800006116 | O23: UNIVERSIDAD DE SANTIAGO DE CHILE | P23: DEPARTAMENTO DE INGENIERÍA INFORMÁTICA | Q23: (4) Business, Management and Accounting | R23: (15) Software Engineering | S23: consorcio, proceso, desarrollo, procesos, sistema, anterior, cambios, compañía, dos, eficiente | T23: (3) Software Design
A24: GUSTAVO ALBERTO SALVO LARA | B24: INGENIERÍA CIVIL EN INFORMÁTICA | C24: DIURNA | E24: BRUNO JERARDINO WIESENBORN | G24: Una aplicación móvil desarrollada con lean UX para el apoyo a los postulantes en el examen teórico de conducción | H24: 2015 | I24: Creative Commons AtribuciónNoComercialSinDerivadas | J24: AUTORIZADO | K24: SI | L24: =IF(K24 = "SI", EXTRA!$C$3, EXTRA!$C$4) | M24: En el presente trabajo se muestra el proceso de desarrollo de una aplicación móvil para dispositivos con sistema operativo Android con el objetivo de apoyar a los postulantes del examen teórico de conducción para la obtención de licencias clase B y C. Se cuenta con la colaboración de la Ilustre Municipalidad de Cerrillos principalmente para establecer el contacto inicial con los postulantes de esa comuna y aclarar dudas sobre la normativa vigente del examen que se realiza. El trabajo constituye un proyecto interno de la Universidad y surge en base al alto porcentaje de reprobación que existe actualmente en el país en el examen teórico de conducción, luego de la nueva implementación a finales del año 2012. El desarrollo del proyecto fue guiado por la metodología Lean UX lo cual permitió generar valor rápidamente a los usuarios mediante la entrega continua de versiones del producto y comprobar los supuestos establecidos al inicio en relación a la problemática que se aborda y el comportamiento de los usuarios con el producto. Junto con la aplicación móvil el proyecto también considera el desarrollo de una plataforma web que permite administrar de forma liviana, sencilla y rápida el contenido que acceden los usuarios desde la aplicación. Actualmente la aplicación se encuentra disponible al público de manera gratuita en Play Store para las personas que poseen dispositivos móviles con sistema operativo Android desde su versión 4.0 en adelante, y desean poner a prueba sus conocimientos teóricos de conducción. | N24: https://usach.primo.exlibrisgroup.com/discovery/delivery/56USACH_INST:REPOSITORIO/1226463500006116 | O24: UNIVERSIDAD DE SANTIAGO DE CHILE | P24: DEPARTAMENTO DE INGENIERÍA INFORMÁTICA | Q24: (7) Computer Science | R24: (14) Software Development Fundamentals | S24: aplicación, conducción, desarrollo, examen, proyecto, usuarios, actualmente, android, dispositivos, móvil | T24: (3) Software Design
A25: NICOLÁS NAZRE NASER ABARZÚA | B25: INGENIERÍA CIVIL EN INFORMÁTICA | C25: DIURNA | E25: ROSA MUÑOZ CALANCHIE | G25: Objeto de aprendizaje para apoyar el proceso de lectura infantil | H25: 2015 | I25: Creative Commons AtribuciónNoComercial | J25: AUTORIZADO | K25: SI | L25: =IF(K25 = "SI", EXTRA!$C$3, EXTRA!$C$4) | M25: Actualmente, existe una gran falencia en comprensión lectora a nivel nacional, una de las maneras de dar solución a esta problemática, es mejorar el proceso desde su inicio, es decir, desde que se aprende a leer. El presente trabajo de titulación consiste en el desarrollo de un Objeto de Aprendizaje que apoye y ayude al proceso de aprendizaje-enseñanza de la lectura en niños de los primeros niveles básicos y pre-escolares. El Objeto de Aprendizaje desarrollado realiza una revisión completa de los contenidos necesarios para lograr ir paso a paso en el desarrollo de la habilidad lectora en los usuarios seleccionados, iniciando con la revisión de las letras, junto a sus grafemas y fonemas, partiendo por las vocales para pasar a las consonantes, pasando a la formación de silabas, palabras y primeras lecturas básicas. Se utilizó la metodología AODDEI para el desarrollo del Objeto de Aprendizaje propuesto. Además, se ocuparon los framework’s Twitter Bootstrap y Jquery, en conjunto de los lenguajes de programación HTML5, CSS3 y PHP. El Objeto de Aprendizaje se validó a través de pruebas de usabilidad, de requerimientos y siguiendo la opinión de expertos en cuanto a los temas metodológicos y conceptuales. Además, se probó con los alumnos de primero básico del colegio “Los Quillayes”, con un resultado exitoso desde el punto de vista pedagógico. Finalmente, es importante mencionar que con el trabajo realizado se obtiene el resultado esperado y se cumple con el desarrollo de una herramienta que apoye el proceso de aprendizaje de la lectura a nivel escolar básico. | N25: https://usach.primo.exlibrisgroup.com/discovery/delivery/56USACH_INST:REPOSITORIO/1226528570006116 | O25: UNIVERSIDAD DE SANTIAGO DE CHILE | P25: DEPARTAMENTO DE INGENIERÍA INFORMÁTICA | Q25: (7) Computer Science | R25: (14) Software Development Fundamentals | S25: aprendizaje, desarrollo, objeto, proceso, además, apoye, básico, lectora, lectura, nivel | T25: (3) Software Design
A26: MAXIMILIANO HERNÁNDEZ SAN MARTÍN | B26: INGENIERÍA CIVIL EN INFORMÁTICA | C26: DIURNA | E26: VÍCTOR PARADA DAZA | G26: Generación de algoritmos utilizando programación genética y coevolución con cambio de entorno para el problema de ordenamiento secuencial | H26: 2015 | I26: Creative Commons AtribuciónNoComercialCompartirIgual | J26: AUTORIZADO | K26: SI | L26: =IF(K26 = "SI", EXTRA!$C$3, EXTRA!$C$4) | M26: El presente trabajo de titulación tiene por objetivo probar un nuevo procedimiento a la hora de realizar evoluciones de algoritmos por medio de la Programación Genética. Para este ejercicio, se ha utilizado para la evaluación el Problema de Ordenamiento Secuencial, que pertenece a la categoría de problemas de optimización y que es una versión más compleja del tradicional problema del Vendedor Viajero. La nueva propuesta de procedimiento está basada en el modelo de dos islas de Chandra y Bali, y consiste en que a partir de dos poblaciones distintas que han evolucionado de forma independiente, se genere una nueva población con los mejores individuos de cada grupo, y se vuelvan a someter a una evolución, con el fin de ver si son capaces de obtener mejores resultados al tomar lo mejor de cada grupo. Para completar el procedimiento se ha utilizado la plataforma ECJ, que está diseñada para realizar procedimientos de Computación Evolutiva, lo cual implica que con la configuración adecuada, permite realizar trabajos con Programación Genética. Se han implementado los pasos que plantea la evolución natural, que son la selección, cruzamiento, mutación y reproducción, para simular este procedimiento y generar algoritmos de forma automatizada mediante el uso de ECJ. Los resultados obtenidos indican que el uso de la coevolución es una variable factible a la hora de buscar formas de mejorar los procesos evolutivos, ya que entrega resultados competitivos. Se ha logrado ver una mejora respecto al proceso tradicional en uno de los algoritmos propuestos. Y se estiman varias posibilidades que permitan mejorar estos resultados en trabajos futuros. | N26: https://usach.primo.exlibrisgroup.com/discovery/delivery/56USACH_INST:REPOSITORIO/1226466050006116 | O26: UNIVERSIDAD DE SANTIAGO DE CHILE | P26: DEPARTAMENTO DE INGENIERÍA INFORMÁTICA | Q26: (7) Computer Science | R26: (1) Algorithms and Complexity | S26: procedimiento, resultados, algoritmos, realizar, cada, dos, ecj, evolución, forma, genética | T26: (19) Research/Investigation
A27: CRISTIAN RICARDO CORNEJO LUENGO | B27: INGENIERÍA CIVIL EN INFORMÁTICA | C27: DIURNA | D27: MAGÍSTER EN INGENIERÍA INFORMÁTICA | E27: MARIO INOSTROZA-PONTA | G27: Algoritmo de agrupamiento para datos de expresión génica de RNA-Seg con la incorporación de anotaciones biológicas | H27: 2015 | I27: Atribución Creative Commons | J27: AUTORIZADO | K27: SI | L27: =IF(K27 = "SI", EXTRA!$C$3, EXTRA!$C$4) | M27: El desarrollo de nuevas tecnologías en el ámbito de la microbiología ha permitido el surgimiento de innovadoras técnicas para cuantificar el nivel de expresión de los genes dentro de una célula. Una de estas es RNA-Seq, la cual está reemplazando a los experimentos de microarreglos en esta a ́rea. Sin embargo, con el surgimiento de esta técnica es necesario un nuevo enfoque en el uso de métodos para el análisis de expresión o la generación de otros. Por otra parte, existen bases de datos que proveen información biológica complementaria sobre los genes, la cual puede ser utilizada como entrada para los métodos de análisis de expresión, y de esta manera, mejorar la coherencia biológica de sus resultados. Este trabajo propone un algoritmo de agrupamiento, basado en el algoritmo MST- kNN para agrupar genes utilizando información del nivel de expresión diferencial de estos, perfiles de expresión y anotaciones biológicas extraídas de Gene Ontology y STRING. La solución propuesta es comparada con el algoritmo MST-kNN, MST-kNN Bio y HTSCluster, usando datos de expresión de RNA-Seq para squamous cell carcinoma. Los resultados obtenidos muestran que el algoritmo propuesto logra agrupar genes con una coherencia biológica superior en hasta un 213% y niveles de coexpresión superiores en hasta un 180%, respecto a los algoritmos en comparación. Adema ́s de obtener particiones distintas con hasta un máximo de 0,16 de similaridad según el indice de Jaccard, utilizando la misma información de entrada que los algoritmos en comparación. De este modo se concluye que el uso de bases de datos, como Gene Ontology y STRING son un aporte para obtener grupos de genes con funcionalidades biológicas similares. Adema ́s el algoritmo propuesto probó ser una solución para el análisis de expresión de datos de RNA-Seq. | N27: https://usach.primo.exlibrisgroup.com/discovery/delivery/56USACH_INST:REPOSITORIO/1226606500006116 | O27: UNIVERSIDAD DE SANTIAGO DE CHILE | P27: DEPARTAMENTO DE INGENIERÍA INFORMÁTICA | Q27: (17) Materials Science | R27: (1) Algorithms and Complexity | S27: expresión, algoritmo, genes, datos, análisis, biológica, información, knn, mst, rna | T27: (19) Research/Investigation
A28: CARLOS ANDRÉS PÉREZ ROJAS | B28: INGENIERÍA CIVIL EN INFORMÁTICA | C28: DIURNA | D28: MAGÍSTER EN INGENIERÍA INFORMÁTICA | E28: GONZALO ACUÑA LEIVA | G28: Elaboración de modelos dinámicos para la predicción de variables de mantenimiento en minería utilizando herramientas de inteligencia computacional | H28: 2015 | I28: Atribución Creative Commons | J28: AUTORIZADO | K28: SI | L28: =IF(K28 = "SI", EXTRA!$C$3, EXTRA!$C$4) | M28: Dentro de la industria minera, las flotas de equipos pesados representan uno de los activos más importantes a nivel de producción. Para mantener estos equipos en condiciones óptimas de funcionamiento, se establecen programa de mantenciones para realizar un chequeo de toda la máquina. Sin embargo, estos programas no siempre son acertados y es común que se requieran realizar mantenciones imprevistas de alguno de los equipos de la flota, con lo cual se ve afectada la productividad de la flota completa. El presente documento muestra el trabajo realizado para diseñar, entrenar y validar un modelo de inteligencia computacional que tiene el fin de predecir la disponibilidad de una flota de ocho palas de la industria minera, para así poder establecer programas de mantención más precisos que beneficien directamente la productividad de estas máquinas, todo esto dentro del marco establecido en el Proyecto Fondef-IDeA CA13I10121. Para llevar a cabo el trabajo se propone utilizar un modelo NARX basado en redes neuronales y se plantean dos enfoques diferentes de entrenamiento, el primero consiste en entrenar un modelo diferente para cada pala y el segundo consiste en entrenar un único modelo para todas las palas. Cada enfoque presenta sus propias ventajas y desventajas. Finalmente se opta por utilizar el segundo enfoque, ya que se considera más adecuado para el área de trabajo. Los resultados obtenidos son alentadores, utilizando como entrenamiento los datos de una sola pala se logra predecir la disponibilidad del resto de las palas con un error promedio por debajo del 25%. Queda en evidencia entonces que es posible aplicar el modelo propuesto en la industria, ya que podría ayudar a generar programas de mantenciones más precisos, mejorando así la productividad de la flota de equipos. | N28: https://usach.primo.exlibrisgroup.com/discovery/delivery/56USACH_INST:REPOSITORIO/1226579450006116 | O28: UNIVERSIDAD DE SANTIAGO DE CHILE | P28: DEPARTAMENTO DE INGENIERÍA INFORMÁTICA | Q28: (7) Computer Science | R28: (3) Artificial Intelligence | S28: modelo, equipos, flota, entrenar, industria, mantenciones, palas, productividad, programas, trabajo | T28: (11) Software Engineering Models and Methods
